Saved 1 image to runs\detect\exp
C:\Users\murra\OneDrive\文件\GitHub\django_bot20240518\mylinebot\celery.py changed, reloading.
Watching for file changes with StatReloader
Performing system checks...

Using cache found in C:\Users\murra/.cache\torch\hub\ultralytics_yolov5_master
requirements: C:\Users\murra\.cache\torch\hub\requirements.txt not found, check failed.
YOLOv5  2023-4-18 Python-3.8.8 torch-2.2.2+cpu CPU

Fusing layers... 
Model summary: 276 layers, 35595240 parameters, 0 gradients, 49.7 GFLOPs
Adding AutoShape...
System check identified no issues (0 silenced).

You have 2 unapplied migration(s). Your project may not work properly until you apply the migrations for app(s): foodbot.
Run 'python manage.py migrate' to apply them.
June 01, 2024 - 22:16:11
Django version 4.2.13, using settings 'mylinebot.settings'
Starting development server at http://127.0.0.1:8000/
Quit the server with CTRL-BREAK.

[ WARN:0@21.840] global loadsave.cpp:248 cv::findDecoder imread_('static\U239861dd3697f3d1e6f9dfe5f729371c(658).png'): can't open/read file: check file path/integrity
Internal Server Error: /foodbot/callback
Traceback (most recent call last):
  File "C:\Users\murra\OneDrive\文件\GitHub\django_bot20240518\venv\lib\site-packages\django\core\handlers\exception.py", line 55, in inner
    response = get_response(request)
  File "C:\Users\murra\OneDrive\文件\GitHub\django_bot20240518\venv\lib\site-packages\django\core\handlers\base.py", line 197, in _get_response
    response = wrapped_callback(request, *callback_args, **callback_kwargs)
  File "C:\Users\murra\OneDrive\文件\GitHub\django_bot20240518\venv\lib\site-packages\django\views\decorators\csrf.py", line 56, in wrapper_view
    return view_func(*args, **kwargs)
  File "C:\Users\murra\OneDrive\文件\GitHub\django_bot20240518\foodbot\views.py", line 86, in callback
    handle_message_event(event)
  File "C:\Users\murra\OneDrive\文件\GitHub\django_bot20240518\foodbot\views.py", line 98, in handle_message_event
    handle_text_message(event)
  File "C:\Users\murra\OneDrive\文件\GitHub\django_bot20240518\foodbot\views.py", line 105, in handle_text_message
    handle_feedback(event)
  File "C:\Users\murra\OneDrive\文件\GitHub\django_bot20240518\foodbot\views.py", line 182, in handle_feedback
    cv2.imwrite(f"./datasets/images/{T}.png", image)
cv2.error: OpenCV(4.9.0) D:\a\opencv-python\opencv-python\opencv\modules\imgcodecs\src\loadsave.cpp:786: error: (-215:Assertion failed) !_img.empty() in function 'cv::imwrite'  

[01/Jun/2024 22:16:26] "POST /foodbot/callback HTTP/1.1" 500 86925
[01/Jun/2024 22:16:43] "GET /static/U239861dd3697f3d1e6f9dfe5f729371c(649).png HTTP/1.1" 200 2675062
Saved 1 image to runs\detect\exp
Internal Server Error: /foodbot/callback
Traceback (most recent call last):
  File "C:\Users\murra\OneDrive\文件\GitHub\django_bot20240518\venv\lib\site-packages\django\core\handlers\exception.py", line 55, in inner
    response = get_response(request)
  File "C:\Users\murra\OneDrive\文件\GitHub\django_bot20240518\venv\lib\site-packages\django\core\handlers\base.py", line 197, in _get_response
    response = wrapped_callback(request, *callback_args, **callback_kwargs)
  File "C:\Users\murra\OneDrive\文件\GitHub\django_bot20240518\venv\lib\site-packages\django\views\decorators\csrf.py", line 56, in wrapper_view
    return view_func(*args, **kwargs)
  File "C:\Users\murra\OneDrive\文件\GitHub\django_bot20240518\foodbot\views.py", line 86, in callback
    handle_message_event(event)
  File "C:\Users\murra\OneDrive\文件\GitHub\django_bot20240518\foodbot\views.py", line 96, in handle_message_event
    handle_image_message(event)
  File "C:\Users\murra\OneDrive\文件\GitHub\django_bot20240518\foodbot\views.py", line 171, in handle_image_message
    line_bot_api.reply_message(event.reply_token, messages)
  File "C:\Users\murra\OneDrive\文件\GitHub\django_bot20240518\venv\lib\site-packages\deprecated\classic.py", line 285, in wrapper_function
    return wrapped_(*args_, **kwargs_)
  File "C:\Users\murra\OneDrive\文件\GitHub\django_bot20240518\venv\lib\site-packages\linebot\api.py", line 123, in reply_message
    self._post(
  File "C:\Users\murra\OneDrive\文件\GitHub\django_bot20240518\venv\lib\site-packages\linebot\api.py", line 2116, in _post
    self.__check_error(response)
  File "C:\Users\murra\OneDrive\文件\GitHub\django_bot20240518\venv\lib\site-packages\linebot\api.py", line 2152, in __check_error
    raise LineBotApiError(
linebot.exceptions.LineBotApiError: LineBotApiError: status_code=400, request_id=b8afe382-574f-406f-afb3-b01730896626, error_response={"details": [], "message": "Invalid reply t
oken"}, headers={'Server': 'legy', 'Content-Type': 'application/json', 'x-content-type-options': 'nosniff', 'x-frame-options': 'DENY', 'x-line-request-id': 'b8afe382-574f-406f-a
fb3-b01730896626', 'x-xss-protection': '1; mode=block', 'Content-Length': '33', 'Expires': 'Sat, 01 Jun 2024 14:17:02 GMT', 'Cache-Control': 'max-age=0, no-cache, no-store', 'Pragma': 'no-cache', 'Date': 'Sat, 01 Jun 2024 14:17:02 GMT', 'Connection': 'close'}
[01/Jun/2024 22:17:03,315] - Broken pipe from ('127.0.0.1', 54507)
[ WARN:1@82.442] global loadsave.cpp:248 cv::findDecoder imread_('static\U239861dd3697f3d1e6f9dfe5f729371c(660).png'): can't open/read file: check file path/integrity
Internal Server Error: /foodbot/callback
Traceback (most recent call last):
  File "C:\Users\murra\OneDrive\文件\GitHub\django_bot20240518\venv\lib\site-packages\django\core\handlers\exception.py", line 55, in inner
    response = get_response(request)
  File "C:\Users\murra\OneDrive\文件\GitHub\django_bot20240518\venv\lib\site-packages\django\core\handlers\base.py", line 197, in _get_response
    response = wrapped_callback(request, *callback_args, **callback_kwargs)
  File "C:\Users\murra\OneDrive\文件\GitHub\django_bot20240518\venv\lib\site-packages\django\views\decorators\csrf.py", line 56, in wrapper_view
    return view_func(*args, **kwargs)
  File "C:\Users\murra\OneDrive\文件\GitHub\django_bot20240518\foodbot\views.py", line 86, in callback
    handle_message_event(event)
  File "C:\Users\murra\OneDrive\文件\GitHub\django_bot20240518\foodbot\views.py", line 98, in handle_message_event
    handle_text_message(event)
  File "C:\Users\murra\OneDrive\文件\GitHub\django_bot20240518\foodbot\views.py", line 105, in handle_text_message
    handle_feedback(event)
  File "C:\Users\murra\OneDrive\文件\GitHub\django_bot20240518\foodbot\views.py", line 182, in handle_feedback
    cv2.imwrite(f"./datasets/images/{T}.png", image)
cv2.error: OpenCV(4.9.0) D:\a\opencv-python\opencv-python\opencv\modules\imgcodecs\src\loadsave.cpp:786: error: (-215:Assertion failed) !_img.empty() in function 'cv::imwrite'  

[01/Jun/2024 22:17:27] "POST /foodbot/callback HTTP/1.1" 500 86925
(venv) PS C:\Users\murra\OneDrive\文件\GitHub\django_bot20240518> python manage.py runserver
Watching for file changes with StatReloader
Performing system checks...

Using cache found in C:\Users\murra/.cache\torch\hub\ultralytics_yolov5_master
requirements: C:\Users\murra\.cache\torch\hub\requirements.txt not found, check failed.
YOLOv5  2023-4-18 Python-3.8.8 torch-2.2.2+cpu CPU

Fusing layers... 
Model summary: 276 layers, 35595240 parameters, 0 gradients, 49.7 GFLOPs
Adding AutoShape...
System check identified no issues (0 silenced).

You have 2 unapplied migration(s). Your project may not work properly until you apply the migrations for app(s): foodbot.
Run 'python manage.py migrate' to apply them.
June 01, 2024 - 22:17:41
